Workbook

Sheet Ders Programı
A1: Çocuk Gastroenteroloji Akademik Eğitim Programı 2026–2027
A2: 15 Eylül 2026 – 15 Haziran 2027 · Salı ve Perşembe · 75 eğitim oturumu
A3: Sarı hücreler doldurulacak alanlardır (Öğretim Üyesi, Yer/Not). Örnek biçim: 'Prof. Dr. A. Yılmaz'
A5: # | B5: Tarih | C5: Gün | D5: Ay | E5: Modül | F5: Konu | G5: Format | H5: Düzey | I5: Öğretim Üyesi | J5: Yer / Not
A6: 1 | B6: 46280 | C6: Salı | D6: Eylül 2026 | E6: Modül 1: Temel Bilimler ve Oryantasyon | F6: Açılış: program hedefleri, yetkinlik çerçevesi, portfolyo ve değerlendirme sistemi (mini-CEX, DOPS tanıtımı); GİS embriyolojisine genel bakış | G6: D | H6: Ç | I6: Prof. Dr. A. Yılmaz (örnek — değiştirin)
A7: 2 | B7: 46282 | C7: Perşembe | D7: Eylül 2026 | E7: Modül 1: Temel Bilimler ve Oryantasyon | F7: GİS anatomi ve histolojisi: endoskopik-mikroskobik korelasyon | G7: D | H7: Ç
A8: 3 | B8: 46287 | C8: Salı | D8: Eylül 2026 | E8: Modül 1: Temel Bilimler ve Oryantasyon | F8: Sindirim ve emilim fizyolojisi: motilite, sekresyon, emilim, enterohepatik dolaşım (ön okuma destekli yoğun oturum) | G8: D | H8: Ç
A9: 4 | B9: 46289 | C9: Perşembe | D9: Eylül 2026 | E9: Modül 1: Temel Bilimler ve Oryantasyon | F9: GİS immünolojisi, bağırsak bariyeri ve mikrobiyota + Modül 1 quiz | G9: D | H9: Ç
A10: 5 | B10: 46294 | C10: Salı | D10: Eylül 2026 | E10: Modül 1: Temel Bilimler ve Oryantasyon | F10: Akut ve kronik karın ağrısına yaklaşım: ayırıcı tanı, alarm bulguları | G10: OT | H10: Ç
A11: 6 | B11: 46296 | C11: Perşembe | D11: Ekim 2026 | E11: Modül 2: Acil ve Sık GİS Sorunlarına Yaklaşım (nöbet-hazırlık bloğu) | F11: Kusmalı çocuğa yaklaşım: yaşa göre ayırıcı tanı | G11: OT | H11: Ç
A12: 7 | B12: 46301 | C12: Salı | D12: Ekim 2026 | E12: Modül 2: Acil ve Sık GİS Sorunlarına Yaklaşım (nöbet-hazırlık bloğu) | F12: İshalli çocuğa yaklaşım: akut-persistan-kronik ayrımı; enfeksiyöz etiyoloji ve parazitozlar | G12: OT | H12: Ç
A13: 8 | B13: 46303 | C13: Perşembe | D13: Ekim 2026 | E13: Modül 2: Acil ve Sık GİS Sorunlarına Yaklaşım (nöbet-hazırlık bloğu) | F13: Kabızlığa yaklaşım; organik nedenlerin dışlanması ve Hirschsprung kırmızı bayrakları | G13: OT | H13: Ç
A14: 9 | B14: 46308 | C14: Salı | D14: Ekim 2026 | E14: Modül 2: Acil ve Sık GİS Sorunlarına Yaklaşım (nöbet-hazırlık bloğu) | F14: Büyüme geriliği ve malnütrisyona yaklaşım: nütrisyonel değerlendirme; vitamin ve eser element eksiklikleri | G14: OT | H14: Ç
A15: 10 | B15: 46310 | C15: Perşembe | D15: Ekim 2026 | E15: Modül 2: Acil ve Sık GİS Sorunlarına Yaklaşım (nöbet-hazırlık bloğu) | F15: GİS kanaması: yaşa göre ayırıcı tanı; varis ve varis dışı kanamanın akut yönetimi | G15: OT | H15: Ç
A16: 11 | B16: 46315 | C16: Salı | D16: Ekim 2026 | E16: Modül 2: Acil ve Sık GİS Sorunlarına Yaklaşım (nöbet-hazırlık bloğu) | F16: Acil hepato-pankreatoloji: akut karaciğer yetmezliğine ilk yaklaşım; akut pankreatitin ilk 48 saati | G16: OT | H16: Ç
A17: 12 | B17: 46317 | C17: Perşembe | D17: Ekim 2026 | E17: Modül 2: Acil ve Sık GİS Sorunlarına Yaklaşım (nöbet-hazırlık bloğu) | F17: Pediatrik endoskopi temelleri: endikasyonlar, bilgilendirilmiş onam, sedasyon, komplikasyonlar | G17: D | H17: Ç
A18: 13 | B18: 46322 | C18: Salı | D18: Ekim 2026 | E18: Modül 2: Acil ve Sık GİS Sorunlarına Yaklaşım (nöbet-hazırlık bloğu) | F18: Pediatrik GİS'te görüntüleme: hangi test, ne zaman? (radyoloji ile ortak oturum) + Modül 2 quiz | G18: P | H18: Ç
B19: 46324 | C19: Perşembe | D19: Ekim 2026 | E19: Modül 2: Acil ve Sık GİS Sorunlarına Yaklaşım (nöbet-hazırlık bloğu) | F19: Cumhuriyet Bayramı — ders yok
A20: 14 | B20: 46329 | C20: Salı | D20: Kasım 2026 | E20: Modül 3: Özofagus ve Mide | F20: Akademik gelişim I: araştırma sorusu ve çalışma tasarımı; fellow proje önerisi sunumları | G20: P | H20: Ç
A21: 15 | B21: 46331 | C21: Perşembe | D21: Kasım 2026 | E21: Modül 3: Özofagus ve Mide | F21: GÖR ve GÖRH: ESPGHAN/NASPGHAN 2018 kılavuzu eşliğinde tanı-tedavi; fundoplikasyon endikasyonları | G21: KO | H21: Ç
A22: 16 | B22: 46336 | C22: Salı | D22: Kasım 2026 | E22: Modül 3: Özofagus ve Mide | F22: Disfaji; özofagus anomalileri ve akalazya | G22: D | H22: Ç
A23: 17 | B23: 46338 | C23: Perşembe | D23: Kasım 2026 | E23: Modül 3: Özofagus ve Mide | F23: Koroziv özofajit ve GİS yabancı cisimleri: acil endoskopik yönetim | G23: OT | H23: Ç
A24: 18 | B24: 46343 | C24: Salı | D24: Kasım 2026 | E24: Modül 3: Özofagus ve Mide | F24: Eozinofilik özofajit ve eozinofilik GİS hastalıkları | G24: D | H24: Ç
A25: 19 | B25: 46345 | C25: Perşembe | D25: Kasım 2026 | E25: Modül 3: Özofagus ve Mide | F25: pH-metre, pH-impedans ve özofagus manometrisi: trase yorumlama pratiği | G25: P | H25: İ
A26: 20 | B26: 46350 | C26: Salı | D26: Kasım 2026 | E26: Modül 3: Özofagus ve Mide | F26: Helicobacter pylori (ESPGHAN/NASPGHAN kılavuzu); gastritler ve peptik ülser | G26: KO | H26: Ç
A27: 21 | B27: 46352 | C27: Perşembe | D27: Kasım 2026 | E27: Modül 3: Özofagus ve Mide | F27: Olgu saati I: özofagus-mide olguları (güncel bir makale ile ilişkilendirilerek) + Modül 3 quiz | G27: OT | H27: Ç
A28: 22 | B28: 46357 | C28: Salı | D28: Aralık 2026 | E28: Modül 4: İnce Bağırsak, Malabsorpsiyon, Çölyak ve Besin Alerjileri | F28: Malabsorpsiyona yaklaşım; karbonhidrat malabsorpsiyonları (laktoz, fruktoz, sükraz-izomaltaz) | G28: D | H28: Ç
A29: 23 | B29: 46359 | C29: Perşembe | D29: Aralık 2026 | E29: Modül 4: İnce Bağırsak, Malabsorpsiyon, Çölyak ve Besin Alerjileri | F29: Çölyak hastalığı I: patogenez, genetik, klinik spektrum | G29: D | H29: Ç
A30: 24 | B30: 46364 | C30: Salı | D30: Aralık 2026 | E30: Modül 4: İnce Bağırsak, Malabsorpsiyon, Çölyak ve Besin Alerjileri | F30: Çölyak hastalığı II: ESPGHAN tanı algoritması, izlem ve diyet uyumu | G30: KO | H30: Ç
A31: 25 | B31: 46366 | C31: Perşembe | D31: Aralık 2026 | E31: Modül 4: İnce Bağırsak, Malabsorpsiyon, Çölyak ve Besin Alerjileri | F31: GİS histopatolojisi I: ince bağırsak biyopsisi ve Marsh-Oberhuber sınıflaması (patoloji ile ortak oturum) | G31: P | H31: İ
... A55: 49 | B55: 46450 | C55: Perşembe | D55: Mart 2027 | E55: Modül 7 Kapanış / Modül 6 Kapanış / Modül 8: Hepatolojiye Giriş | F55: Pankreas III: ekzokrin yetmezlik ve kistik fibrozis; otoimmün pankreatit ve pankreasın kistik lezyonları | G55: D | H55: İ
B56: 46455 | C56: Salı | D56: Mart 2027 | E56: Modül 7 Kapanış / Modül 6 Kapanış / Modül 8: Hepatolojiye Giriş | F56: Ramazan Bayramı (beklenen) — telafi/serbest çalışma günü
B57: 46457 | C57: Perşembe | D57: Mart 2027 | E57: Modül 7 Kapanış / Modül 6 Kapanış / Modül 8: Hepatolojiye Giriş | F57: Ramazan Bayramı (beklenen) — telafi/serbest çalışma günü
A58: 50 | B58: 46462 | C58: Salı | D58: Mart 2027 | E58: Modül 7 Kapanış / Modül 6 Kapanış / Modül 8: Hepatolojiye Giriş | F58: Üst GİS motilite bozuklukları: siklik kusma, ruminasyon, gastroparezi; kronik intestinal psödo-obstrüksiyon ve motilite testlerine genel bakış | G58: D | H58: İ
A59: 51 | B59: 46464 | C59: Perşembe | D59: Mart 2027 | E59: Modül 7 Kapanış / Modül 6 Kapanış / Modül 8: Hepatolojiye Giriş | F59: Karaciğer fonksiyon testleri ve hiperbilirubinemiye yaklaşım; noninvaziv fibroz değerlendirme (elastografi) + Modül 6-7 quiz | G59: D | H59: Ç
A60: 52 | B60: 46469 | C60: Salı | D60: Mart 2027 | E60: Modül 7 Kapanış / Modül 6 Kapanış / Modül 8: Hepatolojiye Giriş | F60: Yenidoğan kolestazına sistematik yaklaşım (NASPGHAN kılavuzu) | G60: KO | H60: Ç
A61: 53 | B61: 46471 | C61: Perşembe | D61: Mart 2027 | E61: Modül 7 Kapanış / Modül 6 Kapanış / Modül 8: Hepatolojiye Giriş | F61: Biliyer atrezi ve Kasai; koledok kisti, safra yolu hastalıkları ve safra taşları | G61: D | H61: Ç
A62: 54 | B62: 46476 | C62: Salı | D62: Mart 2027 | E62: Modül 7 Kapanış / Modül 6 Kapanış / Modül 8: Hepatolojiye Giriş | F62: Genetik kolestatik hastalıklar: PFIC, Alagille ve kistik fibrozis ilişkili karaciğer hastalığı; IBAT inhibitörleri ve yeni tedaviler | G62: D | H62: İ
A63: 55 | B63: 46478 | C63: Perşembe | D63: Nisan 2027 | E63: Modül 8: Hepatoloji | F63: Viral hepatitler I: Hepatit A, E ve C — karşılaştırmalı doğal seyir ve tedavi | G63: D | H63: Ç
A64: 56 | B64: 46483 | C64: Salı | D64: Nisan 2027 | E64: Modül 8: Hepatoloji | F64: Viral hepatitler II: Hepatit B ve D — doğal seyir, tedavi endikasyonları, perinatal korunma | G64: D | H64: Ç
...

Sheet Modül Özeti
A1: Modül ve Format Özeti
A3: Modül | B3: Oturum Sayısı | D3: Format | E3: Oturum | F3: Oran
A4: Modül 1: Temel Bilimler ve Oryantasyon | B4: =COUNTIFS('Ders Programı'!$E$6:$E$84,A4,'Ders Programı'!$A$6:$A$84,">0") -> 5 | D4: D — Didaktik ders | E4: =COUNTIF('Ders Programı'!$G$6:$G$84,"D") -> 39 | F4: =E4/$E$10 -> 0.52
A5: Modül 2: Acil ve Sık GİS Sorunlarına Yaklaşım (nöbet-hazırlık bloğu) | B5: =COUNTIFS('Ders Programı'!$E$6:$E$84,A5,'Ders Programı'!$A$6:$A$84,">0") -> 8 | D5: OT — Olgu temelli | E5: =COUNTIF('Ders Programı'!$G$6:$G$84,"OT") -> 15 | F5: =E5/$E$10 -> 0.2
A6: Modül 3: Özofagus ve Mide | B6: =COUNTIFS('Ders Programı'!$E$6:$E$84,A6,'Ders Programı'!$A$6:$A$84,">0") -> 8 | D6: P — Pratik/ortak oturum | E6: =COUNTIF('Ders Programı'!$G$6:$G$84,"P") -> 9 | F6: =E6/$E$10 -> 0.12
A7: Modül 4: İnce Bağırsak, Malabsorpsiyon, Çölyak ve Besin Alerjileri | B7: =COUNTIFS('Ders Programı'!$E$6:$E$84,A7,'Ders Programı'!$A$6:$A$84,">0") -> 10 | D7: KO — Kılavuz okuma | E7: =COUNTIF('Ders Programı'!$G$6:$G$84,"KO") -> 7 | F7: =E7/$E$10 -> 0.093333333
A8: Modül 5: İnflamatuvar Bağırsak Hastalıkları | B8: =COUNTIFS('Ders Programı'!$E$6:$E$84,A8,'Ders Programı'!$A$6:$A$84,">0") -> 8 | D8: JC — Journal Club | E8: =COUNTIF('Ders Programı'!$G$6:$G$84,"JC") -> 2 | F8: =E8/$E$10 -> 0.026666667
A9: Modül 5 Kapanış / Modül 6: Fonksiyonel GİS ve Motilite / Modül 7 Başlangıcı | B9: =COUNTIFS('Ders Programı'!$E$6:$E$84,A9,'Ders Programı'!$A$6:$A$84,">0") -> 8 | D9: Değ — Değerlendirme | E9: =COUNTIF('Ders Programı'!$G$6:$G$84,"Değ") -> 3 | F9: =E9/$E$10 -> 0.04
A10: Modül 7 Kapanış / Modül 6 Kapanış / Modül 8: Hepatolojiye Giriş | B10: =COUNTIFS('Ders Programı'!$E$6:$E$84,A10,'Ders Programı'!$A$6:$A$84,">0") -> 7 | D10: TOPLAM | E10: =SUM(E4:E9) -> 75
A11: Modül 8: Hepatoloji | B11: =COUNTIFS('Ders Programı'!$E$6:$E$84,A11,'Ders Programı'!$A$6:$A$84,">0") -> 9
A12: Modül 8 Kapanış / Modül 9: Beslenme | B12: =COUNTIFS('Ders Programı'!$E$6:$E$84,A12,'Ders Programı'!$A$6:$A$84,">0") -> 7 | D12: Düzey | E12: Oturum
A13: Modül 10: Endoskopi, Özel Konular ve Kapanış | B13: =COUNTIFS('Ders Programı'!$E$6:$E$84,A13,'Ders Programı'!$A$6:$A$84,">0") -> 5 | D13: Ç — Fellow çekirdek | E13: =COUNTIF('Ders Programı'!$H$6:$H$84,"Ç") -> 58
A14: TOPLAM | B14: =SUM(B4:B13) -> 75 | D14: İ — İleri düzey | E14: =COUNTIF('Ders Programı'!$H$6:$H$84,"İ") -> 17

Sheet Açıklamalar
A1: Açıklamalar ve Değerlendirme Sistemi
A3: Doldurulacak alanlar | B3: ‘Ders Programı’ sayfasında SARI hücreler doldurulur: Öğretim Üyesi ve Yer/Not sütunları. İlk satırda örnek biçim verilmiştir; gerçek adla değiştirin. Diğer hücreler formül/veri içerir, değiştirmeyin.
A4: Formatlar | B4: D: Didaktik ders · OT: Olgu temelli tartışma · JC: Journal Club · KO: Kılavuz okuma (ESPGHAN/NASPGHAN/ESPEN/AASLD) · P: Pratik/beceri/ortak disiplin · Değ: Değerlendirme
A5: Düzeyler | B5: Ç: Fellow çekirdek müfredatı · İ: İleri düzey (kıdemli fellow / öğretim üyesi semineri)
A6: Süreler | B6: Oturumlar 45–60 dk; olgu saatleri ve pratik oturumlar 60 dk.
A7: Formatif değerlendirme | B7: Modül sonu oturumların ilk 10 dakikası kümülatif quiz'dir (programda '+ Modül quiz' olarak işaretli). Endoskopi/manometri pratikleri DOPS / GiECAT-KIDS, klinik değerlendirmeler mini-CEX ile belgelenir.
A8: Ara ve dönem sonu | B8: 28 Ocak: yarıyıl kümülatif sınavı + portfolyo ve proje ara görüşmesi. 10 Haziran: yazılı sınav + OSCE. 15 Haziran: proje sonuç sunumları ve kapanış.
A9: Araştırma izlemi | B9: Proje önerisi (3 Kasım) → ara değerlendirme (28 Ocak) → sonuç sunumu (15 Haziran).
A10: Tatiller | B10: 29 Ekim 2026 Cumhuriyet Bayramı: ders yok. 9–11 Mart ve 18 Mayıs 2027 beklenen dini bayram tarihleridir; Diyanet takvimi kesinleşince güncellenmelidir. Telafi: içerik izleyen haftaya 15 dk özet olarak eklenir veya asenkron kayıt + quiz ile kapatılır.
A11: Ortak oturumlar | B11: Radyoloji (#13, #38), patoloji (#25, #38, #65) ve çocuk cerrahisi (#38) oturumları en az 4 hafta önceden planlanmalıdır.
A12: Kaynak | B12: Bu tablo cocuk-gastroenteroloji-ders-programi-2026-2027.md (v3.1) dosyasından üretilmiştir; program çift hakem değerlendirmesi ve bağımsız takvim denetiminden geçmiştir.
